Workbook
Name creator_rate: creator_rate!$A$1:$D$41
Name cpe: cpe!$A$1:$E$10
Name rate_card: creator_rate!$A$1:$D$13
Name media_tier: media_tier!$A$1:$E$7

Sheet sample
A1: Must fill-in
A2: Automatic formula
A4: CAMPAIGN NAME | C4: RAY-BAN X JEFF SATUR
A5: TEV | C5: INV | E5: ROIM | G5: Media Echo Value | I5: Creator Echo Value | K5: Community Echo Value
A6: =sum(G6,I6,K6) -> 31076575 | C6: 100000000 | E6: =A6/C6 -> 0.31076575 | G6: =sum(G29:G35) -> 14610000 | I6: =sum(I61,I75,I89,I103,I117) -> 16380800 | K6: =sum(K121:K129) -> 85775
A8: CREATOR PROFILE
A10: Creator Name | C10: Jeff Satur
A11: Creator Account | C11: # Followers (thousand) | E11: # Followers (million) | G11: Followers Tier
A12: Facebook | C12: 181 | E12: =C12/1000 -> 0.181 | G12: =IF(C12*1000>=1000000,"Mega", IF(C12*1000>=500000,"Macro", IF(C12*1000>=100000,"Mid-tier", IF(C12*1000>=10000,"Micro", "Nano")))) -> Mid-tier
A14: Instagram | C14: 5600 | E14: =C14/1000 -> 5.6 | G14: =IF(C14*1000>=1000000,"Mega", IF(C14*1000>=500000,"Macro", IF(C14*1000>=100000,"Mid-tier", IF(C14*1000>=10000,"Micro", "Nano")))) -> Mega
A16: TikTok | C16: 3200 | E16: =C16/1000 -> 3.2 | G16: =IF(C16*1000>=1000000,"Mega", IF(C16*1000>=500000,"Macro", IF(C16*1000>=100000,"Mid-tier", IF(C16*1000>=10000,"Micro", "Nano")))) -> Mega
A18: X (Twitter) | C18: 1200 | E18: =C18/1000 -> 1.2 | G18: =IF(C18*1000>=1000000,"Mega", IF(C18*1000>=500000,"Macro", IF(C18*1000>=100000,"Mid-tier", IF(C18*1000>=10000,"Micro", "Nano")))) -> Mega
A20: YouTube | C20: 2000 | E20: =C20/1000 -> 2 | G20: =IF(C20*1000>=1000000,"Mega", IF(C20*1000>=500000,"Macro", IF(C20*1000>=100000,"Mid-tier", IF(C20*1000>=10000,"Micro", "Nano")))) -> Mega
A22: Total Connections | C22: =SUM(C10:C20) -> 12181 | E22: =SUM(E10:E20) -> 12.181 | G22: =IF(C22*1000>=1000000,"Mega", IF(C22*1000>=500000,"Macro", IF(C22*1000>=100000,"Mid-tier", IF(C22*1000>=10000,"Micro", "Nano")))) -> Mega
A25: I. MEDIA ECHO
C26: Mentions/Posts | E26: Tier | G26: Value in ฿
A27: Online Article | C27: =sum(C29:C33) -> 331
A29: Major national media | C29: 181 | E29: =IFERROR(VLOOKUP(A29, media_tier!$B$1:$C$7, 2, FALSE), "Check the data again") -> 1 | G29: =IFERROR(__xludf.DUMMYFUNCTION("IFERROR( IF(A29=""# Online Articles"", C29 * VLOOKUP(E29, FILTER(media_tier!$C$2:$E$10, media_tier!$A$2:$A$10=""Online Article""), 3, FALSE), C29 * VLOOKUP(E29, FILTER(media_tier!$C$2:$E$10, media_tier!$A$2:$A$10=""Social Media""), 3, FALSE) ), ""Ch"&"eck the data again"")"),1.086E7) -> 10860000
A31: Industry-specific | C31: 100 | E31: =IFERROR(VLOOKUP(A31, media_tier!$B$1:$C$7, 2, FALSE), "Check the data again") -> 2 | G31: =IFERROR(__xludf.DUMMYFUNCTION("IFERROR( IF(A31=""# Online Articles"", C31 * VLOOKUP(E31, FILTER(media_tier!$C$2:$E$10, media_tier!$A$2:$A$10=""Online Article""), 3, FALSE), C31 * VLOOKUP(E31, FILTER(media_tier!$C$2:$E$10, media_tier!$A$2:$A$10=""Social Media""), 3, FALSE) ), ""Ch"&"eck the data again"")"),3000000.0) -> 3000000
A33: Local/niche | C33: 50 | E33: =IFERROR(VLOOKUP(A33, media_tier!$B$1:$C$7, 2, FALSE), "Check the data again") -> 3 | G33: =IFERROR(__xludf.DUMMYFUNCTION("IFERROR( IF(A33=""# Online Articles"", C33 * VLOOKUP(E33, FILTER(media_tier!$C$2:$E$10, media_tier!$A$2:$A$10=""Online Article""), 3, FALSE), C33 * VLOOKUP(E33, FILTER(media_tier!$C$2:$E$10, media_tier!$A$2:$A$10=""Social Media""), 3, FALSE) ), ""Ch"&"eck the data again"")"),750000.0) -> 750000
A35: Social Media | C35: =sum(C37:C41) -> 900
A37: 1 | C37: 200 | E37: =IFERROR(VLOOKUP(A37, media_tier!$B$1:$C$7, 2, FALSE), "Check the data again") -> 1 | G37: =IFERROR(__xludf.DUMMYFUNCTION("IFERROR( IF(A37=""# Online Articles"", C37 * VLOOKUP(E37, FILTER(media_tier!$C$2:$E$10, media_tier!$A$2:$A$10=""Online Article""), 3, FALSE), C37 * VLOOKUP(E37, FILTER(media_tier!$C$2:$E$10, media_tier!$A$2:$A$10=""Social Media""), 3, FALSE) ), ""Ch"&"eck the data again"")"),1.2E7) -> 12000000
A39: 2 | C39: 300 | E39: =IFERROR(VLOOKUP(A39, media_tier!$B$1:$C$7, 2, FALSE), "Check the data again") -> 2 | G39: =IFERROR(__xludf.DUMMYFUNCTION("IFERROR( IF(A39=""# Online Articles"", C39 * VLOOKUP(E39, FILTER(media_tier!$C$2:$E$10, media_tier!$A$2:$A$10=""Online Article""), 3, FALSE), C39 * VLOOKUP(E39, FILTER(media_tier!$C$2:$E$10, media_tier!$A$2:$A$10=""Social Media""), 3, FALSE) ), ""Ch"&"eck the data again"")"),9000000.0) -> 9000000
A41: 3 | C41: 400 | E41: =IFERROR(VLOOKUP(A41, media_tier!$B$1:$C$7, 2, FALSE), "Check the data again") -> 3 | G41: =IFERROR(__xludf.DUMMYFUNCTION("IFERROR( IF(A41=""# Online Articles"", C41 * VLOOKUP(E41, FILTER(media_tier!$C$2:$E$10, media_tier!$A$2:$A$10=""Online Article""), 3, FALSE), C41 * VLOOKUP(E41, FILTER(media_tier!$C$2:$E$10, media_tier!$A$2:$A$10=""Social Media""), 3, FALSE) ), ""Ch"&"eck the data again"")"),6000000.0) -> 6000000
A45: Total | C45: =C27+C35 -> 1231 | G45: =sum(G29:G41) -> 41610000
A48: II. CREATOR ECHO
A49: Tier | C49: Nano
A50: Platform | C50: Static/General Post | E50: Video Post | G50: Total Post | I50: Value in ฿
A51: Facebook | C51: 1 | E51: 6 | G51: =C51+E51 -> 7 | I51: {=IFNA( C51 * INDEX( creator_rate!$D$2:$D$99, MATCH( A51&"|"&$C$106&"|"&$C$49, creator_rate!$A$2:$A$99&"|"& creator_rate!$B$2:$B$99&"|"& creator_rate!$C$2:$C$99, 0 ) ), 0 ) + IFNA( E51 * INDEX( creator_rate!$D$2:$D$99, MATCH( A51&"|"&$E$106&"|"&$C$49, creator_rate!$A$2:$A$99&"|"& creator_rate!$B$2:$B$99&"|"& creator_rate!$C$2:$C$99, 0 ) ), 0 )} -> 65200
A53: Instagram | C53: 3 | E53: 2 | G53: =C53+E53 -> 5 | I53: {=IFNA( C53 * INDEX( creator_rate!$D$2:$D$99, MATCH( A53&"|"&$C$106&"|"&$C$49, creator_rate!$A$2:$A$99&"|"& creator_rate!$B$2:$B$99&"|"& creator_rate!$C$2:$C$99, 0 ) ), 0 ) + IFNA( E53 * INDEX( creator_rate!$D$2:$D$99, MATCH( A53&"|"&$E$106&"|"&$C$49, creator_rate!$A$2:$A$99&"|"& creator_rate!$B$2:$B$99&"|"& creator_rate!$C$2:$C$99, 0 ) ), 0 )} -> 42000
A55: TikTok | C55: 0 | E55: 5 | G55: =C55+E55 -> 5 | I55: {=IFNA( C55 * INDEX( creator_rate!$D$2:$D$99, MATCH( A55&"|"&$C$106&"|"&$C$49, creator_rate!$A$2:$A$99&"|"& creator_rate!$B$2:$B$99&"|"& creator_rate!$C$2:$C$99, 0 ) ), 0 ) + IFNA( E55 * INDEX( creator_rate!$D$2:$D$99, MATCH( A55&"|"&$E$106&"|"&$C$49, creator_rate!$A$2:$A$99&"|"& creator_rate!$B$2:$B$99&"|"& creator_rate!$C$2:$C$99, 0 ) ), 0 )} -> 48000
A57: X (Twitter) | C57: 10 | E57: 0 | G57: =C57+E57 -> 10 | I57: {=IFNA( C57 * INDEX( creator_rate!$D$2:$D$99, MATCH( A57&"|"&$C$106&"|"&$C$49, creator_rate!$A$2:$A$99&"|"& creator_rate!$B$2:$B$99&"|"& creator_rate!$C$2:$C$99, 0 ) ), 0 ) + IFNA( E57 * INDEX( creator_rate!$D$2:$D$99, MATCH( A57&"|"&$E$106&"|"&$C$49, creator_rate!$A$2:$A$99&"|"& creator_rate!$B$2:$B$99&"|"& creator_rate!$C$2:$C$99, 0 ) ), 0 )} -> 50000
A59: YouTube | C59: 0 | E59: 1 | G59: =C59+E59 -> 1 | I59: {=IFNA( C59 * INDEX( creator_rate!$D$2:$D$99, MATCH( A59&"|"&$C$106&"|"&$C$49, creator_rate!$A$2:$A$99&"|"& creator_rate!$B$2:$B$99&"|"& creator_rate!$C$2:$C$99, 0 ) ), 0 ) + IFNA( E59 * INDEX( creator_rate!$D$2:$D$99, MATCH( A59&"|"&$E$106&"|"&$C$49, creator_rate!$A$2:$A$99&"|"& creator_rate!$B$2:$B$99&"|"& creator_rate!$C$2:$C$99, 0 ) ), 0 )} -> 9600
A61: Total | C61: =sum(C51:C59) -> 14 | E61: =sum(E51:E59) -> 14 | G61: =sum(G51:G59) -> 28 | I61: =sum(I51:I59) -> 214800
A63: Tier | C63: Micro
A64: Platform | C64: Static/General Post | E64: Video Post | G64: Total Post | I64: Value in ฿
A65: Facebook | C65: 1 | E65: 6 | G65: =C65+E65 -> 7 | I65: {=IFNA( C65 * INDEX( creator_rate!$D$2:$D$99, MATCH( A65&"|"&$C$106&"|"&$C$63, creator_rate!$A$2:$A$99&"|"& creator_rate!$B$2:$B$99&"|"& creator_rate!$C$2:$C$99, 0 ) ), 0 ) + IFNA( E65 * INDEX( creator_rate!$D$2:$D$99, MATCH( A65&"|"&$E$106&"|"&$C$63, creator_rate!$A$2:$A$99&"|"& creator_rate!$B$2:$B$99&"|"& creator_rate!$C$2:$C$99, 0 ) ), 0 )} -> 505000
A67: Instagram | C67: 3 | E67: 2 | G67: =C67+E67 -> 5 | I67: {=IFNA( C67 * INDEX( creator_rate!$D$2:$D$99, MATCH( A67&"|"&$C$106&"|"&$C$63, creator_rate!$A$2:$A$99&"|"& creator_rate!$B$2:$B$99&"|"& creator_rate!$C$2:$C$99, 0 ) ), 0 ) + IFNA( E67 * INDEX( creator_rate!$D$2:$D$99, MATCH( A67&"|"&$E$106&"|"&$C$63, creator_rate!$A$2:$A$99&"|"& creator_rate!$B$2:$B$99&"|"& creator_rate!$C$2:$C$99, 0 ) ), 0 )} -> 299000
A69: TikTok | C69: 0 | E69: 5 | G69: =C69+E69 -> 5 | I69: {=IFNA( C69 * INDEX( creator_rate!$D$2:$D$99, MATCH( A69&"|"&$C$106&"|"&$C$63, creator_rate!$A$2:$A$99&"|"& creator_rate!$B$2:$B$99&"|"& creator_rate!$C$2:$C$99, 0 ) ), 0 ) + IFNA( E69 * INDEX( creator_rate!$D$2:$D$99, MATCH( A69&"|"&$E$106&"|"&$C$63, creator_rate!$A$2:$A$99&"|"& creator_rate!$B$2:$B$99&"|"& creator_rate!$C$2:$C$99, 0 ) ), 0 )} -> 380000
A71: X (Twitter) | C71: 10 | E71: 0 | G71: =C71+E71 -> 10 | I71: {=IFNA( C71 * INDEX( creator_rate!$D$2:$D$99, MATCH( A71&"|"&$C$106&"|"&$C$63, creator_rate!$A$2:$A$99&"|"& creator_rate!$B$2:$B$99&"|"& creator_rate!$C$2:$C$99, 0 ) ), 0 ) + IFNA( E71 * INDEX( creator_rate!$D$2:$D$99, MATCH( A71&"|"&$E$106&"|"&$C$63, creator_rate!$A$2:$A$99&"|"& creator_rate!$B$2:$B$99&"|"& creator_rate!$C$2:$C$99, 0 ) ), 0 )} -> 150000
...

Sheet media_tier
A1: Category | B1: Type | C1: Tier | D1: Criteria | E1: Tier Value (Advertising Rate) (฿)
A2: Online Article | B2: Major national media | C2: 1 | D2: To be defined (e.g., Major National News) | E2: 60000
A3: Online Article | B3: Industry-specific | C3: 2 | D3: To be defined (e.g., Industry-Specific Media) | E3: 30000
A4: Online Article | B4: Local/niche | C4: 3 | D4: To be defined (e.g., Niche Blogs, Local News) | E4: 15000
A5: Social Media | B5: 1 | C5: 1 | D5: >=100,000 Followers | E5: 60000
A6: Social Media | B6: 2 | C6: 2 | D6: 30,000-99,999 Followers | E6: 30000
A7: Social Media | B7: 3 | C7: 3 | D7: <30,000 Followers | E7: 15000

Sheet creator_rate
A1: Platform | B1: Type | C1: Tier | D1: Rate
A2: Instagram | B2: Static/General Post | C2: Mega | D2: 280000
A3: Instagram | B3: Video Post | C3: Mega | D3: 495000
A4: TikTok | B4: Video Post | C4: Mega | D4: 297000
A5: Facebook | B5: Static/General Post | C5: Mega | D5: 280000
A6: Facebook | B6: Video Post | C6: Mega | D6: 297000
A7: YouTube | B7: Video Post | C7: Mega | D7: 495000
A8: X (Twitter) | B8: Static/General Post | C8: Mega | D8: 50000
A9: Lemon 8 | B9: Static/General Post | C9: Mega | D9: 50000
A10: Instagram | B10: Static/General Post | C10: Macro | D10: 188000
A11: Instagram | B11: Video Post | C11: Macro | D11: 280000
A12: TikTok | B12: Video Post | C12: Macro | D12: 280000
A13: Facebook | B13: Static/General Post | C13: Macro | D13: 188000
... A41: Lemon 8 | B41: Static/General Post | C41: Nano | D41: 5000

Sheet cpe
A1: Platform | B1: Content Creation (New Posts, Videos) | C1: Passive Engagement (Likes, Reactions) | D1: Active Engagement (Comments, Replies) | E1: Amplification (Shares, Retweets)
A2: Facebook | B2: 525 | C2: 3.25 | D2: 11.5 | E2: 27.5
A3: Instagram | B3: 875 | C3: 4.25 | D3: 17.5 | E3: 37.5
A4: TikTok | B4: 600 | C4: 2.5 | D4: 9.5 | E4: 40
A5: X (Twitter) | B5: 425 | C5: 4 | D5: 14 | E5: 32.5
A6: YouTube | B6: 0 | C6: 3 | D6: 15 | E6: 0
